<?xml version="1.0" ?>
<!-- =================================================================================== -->
<!-- |    This document was autogenerated by xacro from cygnus.urdf.xacro              | -->
<!-- |    EDITING THIS FILE BY HAND IS NOT RECOMMENDED                                 | -->
<!-- =================================================================================== -->
<robot name="cygnus">
  <material name="silver">
    <color rgba="0.700 0.700 0.700 1.000"/>
  </material>
  <transmission name="Joint_Flipper_Front_Right_tran">
    <type>transmission_interface/SimpleTransmission</type>
    <joint name="Joint_Flipper_Front_Right">
      <hardwareInterface>hardware_interface/EffortJointInterface</hardwareInterface>
    </joint>
    <actuator name="Joint_Flipper_Front_Right_actr">
      <hardwareInterface>hardware_interface/EffortJointInterface</hardwareInterface>
      <mechanicalReduction>1</mechanicalReduction>
    </actuator>
  </transmission>
  <transmission name="Joint_Flipper_Front_Left_tran">
    <type>transmission_interface/SimpleTransmission</type>
    <joint name="Joint_Flipper_Front_Left">
      <hardwareInterface>hardware_interface/EffortJointInterface</hardwareInterface>
    </joint>
    <actuator name="Joint_Flipper_Front_Left_actr">
      <hardwareInterface>hardware_interface/EffortJointInterface</hardwareInterface>
      <mechanicalReduction>1</mechanicalReduction>
    </actuator>
  </transmission>
  <transmission name="Joint_Flipper_Back_Right_tran">
    <type>transmission_interface/SimpleTransmission</type>
    <joint name="Joint_Flipper_Back_Right">
      <hardwareInterface>hardware_interface/EffortJointInterface</hardwareInterface>
    </joint>
    <actuator name="Joint_Flipper_Back_Right_actr">
      <hardwareInterface>hardware_interface/EffortJointInterface</hardwareInterface>
      <mechanicalReduction>1</mechanicalReduction>
    </actuator>
  </transmission>
  <transmission name="Joint_Flipper_Back_Left_tran">
    <type>transmission_interface/SimpleTransmission</type>
    <joint name="Joint_Flipper_Back_Left">
      <hardwareInterface>hardware_interface/EffortJointInterface</hardwareInterface>
    </joint>
    <actuator name="Joint_Flipper_Back_Left_actr">
      <hardwareInterface>hardware_interface/EffortJointInterface</hardwareInterface>
      <mechanicalReduction>1</mechanicalReduction>
    </actuator>
  </transmission>
  <gazebo>
    <plugin filename="libgazebo_ros_control.so" name="control"/>
  </gazebo>
  <gazebo reference="base_link">
    <material>Gazebo/Silver</material>
    <mu1>0.2</mu1>
    <mu2>0.2</mu2>
    <selfCollide>true</selfCollide>
    <gravity>true</gravity>
  </gazebo>
  <gazebo reference="flipper_front_right_1">
    <material>Gazebo/Silver</material>
    <mu1>0.2</mu1>
    <mu2>0.2</mu2>
    <selfCollide>true</selfCollide>
  </gazebo>
  <gazebo reference="flipper_front_left_1">
    <material>Gazebo/Silver</material>
    <mu1>0.2</mu1>
    <mu2>0.2</mu2>
    <selfCollide>true</selfCollide>
  </gazebo>
  <gazebo reference="flipper_back_right_1">
    <material>Gazebo/Silver</material>
    <mu1>0.2</mu1>
    <mu2>0.2</mu2>
    <selfCollide>true</selfCollide>
  </gazebo>
  <gazebo reference="flipper_back_left_1">
    <material>Gazebo/Silver</material>
    <mu1>0.2</mu1>
    <mu2>0.2</mu2>
    <selfCollide>true</selfCollide>
  </gazebo>
  <link name="base_link">
    <inertial>
      <origin rpy="0 0 0" xyz="-3.381256321980912e-05 -2.4978577981486274e-06 0.034989012896369985"/>
      <mass value="7.297199838788111"/>
      <inertia ixx="0.017571" ixy="2e-06" ixz="8e-06" iyy="0.041038" iyz="1e-06" izz="0.052761"/>
    </inertial>
    <visual>
      <origin rpy="0 0 0" xyz="0 0 0"/>
      <geometry>
        <mesh filename="package://cygnus_description/meshes/base_link.stl" scale="0.001 0.001 0.001"/>
      </geometry>
      <material name="silver"/>
    </visual>
    <collision>
      <origin rpy="0 0 0" xyz="0 0 0"/>
      <geometry>
        <mesh filename="package://cygnus_description/meshes/base_link.stl" scale="0.001 0.001 0.001"/>
      </geometry>
    </collision>
  </link>
  <link name="flipper_front_right_1">
    <inertial>
      <origin rpy="0 0 0" xyz="0.075 -0.015 0.0"/>
      <mass value="1.1622245310524473"/>
      <inertia ixx="0.00053" ixy="0.0" ixz="0.0" iyy="0.004581" iyz="-0.0" izz="0.004225"/>
    </inertial>
    <visual>
      <origin rpy="0 0 0" xyz="-0.075 0.085 -0.035"/>
      <geometry>
        <mesh filename="package://cygnus_description/meshes/flipper_front_right_1.stl" scale="0.001 0.001 0.001"/>
      </geometry>
      <material name="silver"/>
    </visual>
    <collision>
      <origin rpy="0 0 0" xyz="-0.075 0.085 -0.035"/>
      <geometry>
        <mesh filename="package://cygnus_description/meshes/flipper_front_right_1.stl" scale="0.001 0.001 0.001"/>
      </geometry>
    </collision>
  </link>
  <link name="flipper_front_left_1">
    <inertial>
      <origin rpy="0 0 0" xyz="0.07500000000000002 0.015 -6.938893903907228e-18"/>
      <mass value="1.1622245310524475"/>
      <inertia ixx="0.00053" ixy="0.0" ixz="0.0" iyy="0.004581" iyz="0.0" izz="0.004225"/>
    </inertial>
    <visual>
      <origin rpy="0 0 0" xyz="-0.075 -0.085 -0.035"/>
      <geometry>
        <mesh filename="package://cygnus_description/meshes/flipper_front_left_1.stl" scale="0.001 0.001 0.001"/>
      </geometry>
      <material name="silver"/>
    </visual>
    <collision>
      <origin rpy="0 0 0" xyz="-0.075 -0.085 -0.035"/>
      <geometry>
        <mesh filename="package://cygnus_description/meshes/flipper_front_left_1.stl" scale="0.001 0.001 0.001"/>
      </geometry>
    </collision>
  </link>
  <link name="flipper_back_right_1">
    <inertial>
      <origin rpy="0 0 0" xyz="-0.07500000000000005 -0.015 -6.938893903907228e-18"/>
      <mass value="1.1622245310524477"/>
      <inertia ixx="0.00053" ixy="0.0" ixz="-0.0" iyy="0.004581" iyz="0.0" izz="0.004225"/>
    </inertial>
    <visual>
      <origin rpy="0 0 0" xyz="0.075 0.085 -0.035"/>
      <geometry>
        <mesh filename="package://cygnus_description/meshes/flipper_back_right_1.stl" scale="0.001 0.001 0.001"/>
      </geometry>
      <material name="silver"/>
    </visual>
    <collision>
      <origin rpy="0 0 0" xyz="0.075 0.085 -0.035"/>
      <geometry>
        <mesh filename="package://cygnus_description/meshes/flipper_back_right_1.stl" scale="0.001 0.001 0.001"/>
      </geometry>
    </collision>
  </link>
  <link name="flipper_back_left_1">
    <inertial>
      <origin rpy="0 0 0" xyz="-0.09000000000000001 0.015 0.0"/>
      <mass value="1.3323245310524472"/>
      <inertia ixx="0.000612" ixy="0.0" ixz="0.0" iyy="0.006722" iyz="0.0" izz="0.006309"/>
    </inertial>
    <visual>
      <origin rpy="0 0 0" xyz="0.075 -0.085 -0.035"/>
      <geometry>
        <mesh filename="package://cygnus_description/meshes/flipper_back_left_1.stl" scale="0.001 0.001 0.001"/>
      </geometry>
      <material name="silver"/>
    </visual>
    <collision>
      <origin rpy="0 0 0" xyz="0.075 -0.085 -0.035"/>
      <geometry>
        <mesh filename="package://cygnus_description/meshes/flipper_back_left_1.stl" scale="0.001 0.001 0.001"/>
      </geometry>
    </collision>
  </link>
  <joint name="Joint_Flipper_Front_Right" type="continuous">
    <origin rpy="0 0 0" xyz="0.075 -0.085 0.035"/>
    <parent link="base_link"/>
    <child link="flipper_front_right_1"/>
    <axis xyz="0.0 -1.0 0.0"/>
  </joint>
  <joint name="Joint_Flipper_Front_Left" type="continuous">
    <origin rpy="0 0 0" xyz="0.075 0.085 0.035"/>
    <parent link="base_link"/>
    <child link="flipper_front_left_1"/>
    <axis xyz="0.0 1.0 0.0"/>
  </joint>
  <joint name="Joint_Flipper_Back_Right" type="continuous">
    <origin rpy="0 0 0" xyz="-0.075 -0.085 0.035"/>
    <parent link="base_link"/>
    <child link="flipper_back_right_1"/>
    <axis xyz="0.0 -1.0 0.0"/>
  </joint>
  <joint name="Joint_Flipper_Back_Left" type="continuous">
    <origin rpy="0 0 0" xyz="-0.075 0.085 0.035"/>
    <parent link="base_link"/>
    <child link="flipper_back_left_1"/>
    <axis xyz="0.0 1.0 0.0"/>
  </joint>
  <ros2_control name="FakeSystem" type="system">
    <hardware>
      <!-- By default, set up controllers for simulation. This won't work on real hardware -->
      <!--plugin>mock_components/GenericSystem</plugin-->
      <plugin>topic_based_ros2_control/TopicBasedSystem</plugin>
      <param name="joint_commands_topic">/isaac_joint_commands</param>
      <param name="joint_states_topic">/isaac_joint_states</param>
    </hardware>
    <joint name="Joint_Flipper_Back_Left">
      <command_interface name="position"/>
      <state_interface name="position">
        <param name="initial_value">0</param>
      </state_interface>
      <state_interface name="velocity"/>
    </joint>
    <joint name="Joint_Flipper_Back_Right">
      <command_interface name="position"/>
      <state_interface name="position">
        <param name="initial_value">0</param>
      </state_interface>
      <state_interface name="velocity"/>
    </joint>
    <joint name="Joint_Flipper_Front_Left">
      <command_interface name="position"/>
      <state_interface name="position">
        <param name="initial_value">0</param>
      </state_interface>
      <state_interface name="velocity"/>
    </joint>
    <joint name="Joint_Flipper_Front_Right">
      <command_interface name="position"/>
      <state_interface name="position">
        <param name="initial_value">0</param>
      </state_interface>
      <state_interface name="velocity"/>
    </joint>
  </ros2_control>
</robot>
