<?xml version="1.0" ?>
<robot name="cygnus" xmlns:xacro="http://www.ros.org/wiki/xacro">

<xacro:include filename="$(find cygnus_description)/urdf/materials.xacro" />
<xacro:include filename="$(find cygnus_description)/urdf/cygnus.trans" />
<xacro:include filename="$(find cygnus_description)/urdf/cygnus.gazebo" />
<link name="base_link">
  <inertial>
    <origin xyz="-3.381256321980912e-05 -2.4978577981486274e-06 0.034989012896369985" rpy="0 0 0"/>
    <mass value="7.297199838788111"/>
    <inertia ixx="0.017571" iyy="0.041038" izz="0.052761" ixy="2e-06" iyz="1e-06" ixz="8e-06"/>
  </inertial>
  <visual>
    <origin xyz="0 0 0" rpy="0 0 0"/>
    <geometry>
      <mesh filename="package://cygnus_description/meshes/base_link.stl" scale="0.001 0.001 0.001"/>
    </geometry>
    <material name="silver"/>
  </visual>
  <collision>
    <origin xyz="0 0 0" rpy="0 0 0"/>
    <geometry>
      <mesh filename="package://cygnus_description/meshes/base_link.stl" scale="0.001 0.001 0.001"/>
    </geometry>
  </collision>
</link>

<link name="flipper_front_right_1">
  <inertial>
    <origin xyz="0.075 -0.015 0.0" rpy="0 0 0"/>
    <mass value="1.1622245310524473"/>
    <inertia ixx="0.00053" iyy="0.004581" izz="0.004225" ixy="0.0" iyz="-0.0" ixz="0.0"/>
  </inertial>
  <visual>
    <origin xyz="-0.075 0.085 -0.035" rpy="0 0 0"/>
    <geometry>
      <mesh filename="package://cygnus_description/meshes/flipper_front_right_1.stl" scale="0.001 0.001 0.001"/>
    </geometry>
    <material name="silver"/>
  </visual>
  <collision>
    <origin xyz="-0.075 0.085 -0.035" rpy="0 0 0"/>
    <geometry>
      <mesh filename="package://cygnus_description/meshes/flipper_front_right_1.stl" scale="0.001 0.001 0.001"/>
    </geometry>
  </collision>
</link>

<link name="flipper_front_left_1">
  <inertial>
    <origin xyz="0.07500000000000002 0.015 -6.938893903907228e-18" rpy="0 0 0"/>
    <mass value="1.1622245310524475"/>
    <inertia ixx="0.00053" iyy="0.004581" izz="0.004225" ixy="0.0" iyz="0.0" ixz="0.0"/>
  </inertial>
  <visual>
    <origin xyz="-0.075 -0.085 -0.035" rpy="0 0 0"/>
    <geometry>
      <mesh filename="package://cygnus_description/meshes/flipper_front_left_1.stl" scale="0.001 0.001 0.001"/>
    </geometry>
    <material name="silver"/>
  </visual>
  <collision>
    <origin xyz="-0.075 -0.085 -0.035" rpy="0 0 0"/>
    <geometry>
      <mesh filename="package://cygnus_description/meshes/flipper_front_left_1.stl" scale="0.001 0.001 0.001"/>
    </geometry>
  </collision>
</link>

<link name="flipper_back_right_1">
  <inertial>
    <origin xyz="-0.07500000000000005 -0.015 -6.938893903907228e-18" rpy="0 0 0"/>
    <mass value="1.1622245310524477"/>
    <inertia ixx="0.00053" iyy="0.004581" izz="0.004225" ixy="0.0" iyz="0.0" ixz="-0.0"/>
  </inertial>
  <visual>
    <origin xyz="0.075 0.085 -0.035" rpy="0 0 0"/>
    <geometry>
      <mesh filename="package://cygnus_description/meshes/flipper_back_right_1.stl" scale="0.001 0.001 0.001"/>
    </geometry>
    <material name="silver"/>
  </visual>
  <collision>
    <origin xyz="0.075 0.085 -0.035" rpy="0 0 0"/>
    <geometry>
      <mesh filename="package://cygnus_description/meshes/flipper_back_right_1.stl" scale="0.001 0.001 0.001"/>
    </geometry>
  </collision>
</link>

<link name="flipper_back_left_1">
  <inertial>
    <origin xyz="-0.09000000000000001 0.015 0.0" rpy="0 0 0"/>
    <mass value="1.3323245310524472"/>
    <inertia ixx="0.000612" iyy="0.006722" izz="0.006309" ixy="0.0" iyz="0.0" ixz="0.0"/>
  </inertial>
  <visual>
    <origin xyz="0.075 -0.085 -0.035" rpy="0 0 0"/>
    <geometry>
      <mesh filename="package://cygnus_description/meshes/flipper_back_left_1.stl" scale="0.001 0.001 0.001"/>
    </geometry>
    <material name="silver"/>
  </visual>
  <collision>
    <origin xyz="0.075 -0.085 -0.035" rpy="0 0 0"/>
    <geometry>
      <mesh filename="package://cygnus_description/meshes/flipper_back_left_1.stl" scale="0.001 0.001 0.001"/>
    </geometry>
  </collision>
</link>

<joint name="Joint_Flipper_Front_Right" type="continuous">
  <origin xyz="0.075 -0.085 0.035" rpy="0 0 0"/>
  <parent link="base_link"/>
  <child link="flipper_front_right_1"/>
  <axis xyz="0.0 -1.0 0.0"/>
</joint>

<joint name="Joint_Flipper_Front_Left" type="continuous">
  <origin xyz="0.075 0.085 0.035" rpy="0 0 0"/>
  <parent link="base_link"/>
  <child link="flipper_front_left_1"/>
  <axis xyz="0.0 1.0 0.0"/>
</joint>

<joint name="Joint_Flipper_Back_Right" type="continuous">
  <origin xyz="-0.075 -0.085 0.035" rpy="0 0 0"/>
  <parent link="base_link"/>
  <child link="flipper_back_right_1"/>
  <axis xyz="0.0 -1.0 0.0"/>
</joint>

<joint name="Joint_Flipper_Back_Left" type="continuous">
  <origin xyz="-0.075 0.085 0.035" rpy="0 0 0"/>
  <parent link="base_link"/>
  <child link="flipper_back_left_1"/>
  <axis xyz="0.0 1.0 0.0"/>
</joint>

</robot>
